<?xml version="1.0"?>

<robot name="Anton" xmlns:xacro="http://www.ros.org/wiki/xacro">
 
  <xacro:macro name="cylinder_inertia" params="m r h">
      <inertial>
        <origin xyz="0 0 0" rpy="${pi/2} 0 0" />
        <mass value="${m}"/>
        <inertia ixx="${(m/12) * (3*r*r + h*h)}" ixy = "0" ixz = "0" iyy="${(m/12) * (3*r*r + h*h)}" iyz = "0" izz="${(m/2) * (r*r)}"/>
      </inertial>
  </xacro:macro>

  <xacro:macro name="wheel" params="prefix x_reflect y_reflect">
    <link name="${prefix}_link">
      <visual>
        <origin xyz="0 0 0" rpy="${pi/2} 0 0"/>
        <geometry>
            <cylinder radius="${wheel_radius}" length="${wheel_width}"/>
        </geometry>
        <material name="Gray">
          <color rgba="0.5 0.5 0.5 1.0"/>
        </material>
      </visual>
      	

      <collision>
        <origin xyz="0 0 0" rpy="${pi/2} 0 0"/>
        <geometry>
          <cylinder radius="${wheel_radius}" length="${wheel_width}"/>
        </geometry>
        <surface>
        <friction>
          <ode>
            <mu>0.05</mu>
            <mu2>0.05</mu2>
          </ode>
        </friction>
      </surface>
      </collision>

      <xacro:cylinder_inertia m="5" r="${wheel_radius}" h="${wheel_width}"/>

    </link>

    <joint name="${prefix}_joint" type="continuous">
      <parent link="base_link"/>
      <child link="${prefix}_link"/>
      <origin xyz="${x_reflect*wheel_xoff} ${y_reflect*(base_width/2+wheel_ygap)} ${-wheel_zoff}" rpy="0 0 0"/>
      <axis xyz="0 1 0"/>
    </joint>
  </xacro:macro>

  <xacro:wheel prefix="drivewhl_l" x_reflect="-1" y_reflect="1" />
  <xacro:wheel prefix="drivewhl_r" x_reflect="-1" y_reflect="-1" />

</robot>
